Workbook

Sheet Customers
A1: Customer_ID | B1: Age | C1: Gender | D1: Province | E1: City | F1: Branch_ID | G1: Customer_Segment | H1: Join_Date
A2: C00001 | B2: 64 | C2: Male | D2: Lusaka | E2: Lusaka | F2: B003 | G2: Individual | H2: 46044
A3: C00002 | B3: 29 | C3: Male | D3: Eastern | E3: Chipata | F3: B010 | G3: Student | H3: 45707 | L3: Row Labels | M3: Count of Customer_Segment
A4: C00003 | B4: 33 | C4: Male | D4: Southern | E4: Livingstone | F4: B007 | G4: SME | H4: 46121 | L4: Corporate | M4: 63
A5: C00004 | B5: 41 | C5: Female | D5: Copperbelt | E5: Kitwe | F5: B005 | G5: Individual | H5: 45532 | L5: Individual | M5: 582
A6: C00005 | B6: 36 | C6: Female | D6: Lusaka | E6: Lusaka | F6: B001 | G6: SME | H6: 45587 | L6: SME | M6: 237
A7: C00006 | B7: 25 | C7: Male | D7: Lusaka | E7: Lusaka | F7: B001 | G7: SME | H7: 45775 | L7: Student | M7: 118
A8: C00007 | B8: 48 | C8: Male | D8: Lusaka | E8: Lusaka | F8: B001 | G8: Individual | H8: 45862 | L8: Grand Total | M8: 1000
A9: C00008 | B9: 38 | C9: Male | D9: Western | E9: Mongu | F9: B009 | G9: Individual | H9: 45554
A10: C00009 | B10: 34 | C10: Female | D10: Copperbelt | E10: Kitwe | F10: B005 | G10: Individual | H10: 45069
A11: C00010 | B11: 40 | C11: Female | D11: Copperbelt | E11: Ndola | F11: B006 | G11: SME | H11: 46151 | L11: Row Labels | M11: Count of Province
A12: C00011 | B12: 54 | C12: Female | D12: Lusaka | E12: Lusaka | F12: B001 | G12: Individual | H12: 46130 | L12: Central | M12: 62
A13: C00012 | B13: 33 | C13: Female | D13: Eastern | E13: Chipata | F13: B010 | G13: Individual | H13: 45640 | L13: Copperbelt | M13: 219
A14: C00013 | B14: 23 | C14: Unknown | D14: Central | E14: Kabwe | F14: B008 | G14: Individual | H14: 45405 | L14: Eastern | M14: 68
A15: C00014 | B15: 25 | C15: Female | D15: Lusaka | E15: Lusaka | F15: B002 | G15: Individual | H15: 45491 | L15: Lusaka | M15: 503
A16: C00015 | B16: 42 | C16: Male | D16: Lusaka | E16: Lusaka | F16: B002 | G16: Individual | H16: 45397 | L16: Lusaka Province | M16: 1
A17: C00016 | B17: 35 | C17: Female | D17: Lusaka | E17: Lusaka | F17: B002 | G17: Individual | H17: 45310 | L17: Southern | M17: 62
A18: C00017 | B18: 42 | C18: Male | D18: Lusaka | E18: Lusaka | F18: B003 | G18: SME | H18: 45852 | L18: Western | M18: 85
A19: C00018 | B19: 29 | C19: Female | D19: Copperbelt | E19: Kitwe | F19: B005 | G19: Individual | H19: 45343 | L19: Grand Total | M19: 1000
A20: C00019 | B20: 32 | C20: Male | D20: Lusaka | E20: Lusaka | F20: B004 | G20: Individual | H20: 45234
A21: C00020 | B21: 43 | C21: Female | D21: Lusaka | E21: Lusaka | F21: B003 | G21: Individual | H21: 45575
A22: C00021 | B22: 58 | C22: Female | D22: Copperbelt | E22: Ndola | F22: B006 | G22: SME | H22: 45951 | K22: Maximum age | L22: =MAX(B:B) -> 65
A23: C00022 | B23: 62 | C23: Female | D23: Lusaka | E23: Lusaka | F23: B001 | G23: Individual | H23: 45994 | K23: Maximum age | L23: =MIN(B:B) -> 18
A24: C00023 | B24: 43 | C24: Female | D24: Lusaka | E24: Lusaka | F24: B003 | G24: SME | H24: 45665
A25: C00024 | B25: 64 | C25: Male | D25: Lusaka | E25: Lusaka | F25: B003 | G25: Individual | H25: 46048 | K25: Total Customer IDs | L25: =COUNTA(A2:A1001) -> 1000
A26: C00025 | B26: 49 | C26: Male | D26: Lusaka | E26: Lusaka | F26: B004 | G26: Individual | H26: 45066 | M26: =COUNTA(UNIQUE(A2:A1001)) -> 1
A27: C00026 | B27: 27 | C27: Male | D27: Central | E27: Kabwe | F27: B008 | G27: Student | H27: 46187
A28: C00027 | B28: 33 | C28: Male | D28: Lusaka | E28: Lusaka | F28: B002 | G28: Student | H28: 45900
A29: C00028 | B29: 24 | C29: Female | D29: Copperbelt | E29: Kitwe | F29: B005 | G29: Individual | H29: 45943
A30: C00029 | B30: 34 | C30: Male | D30: Copperbelt | E30: Kitwe | F30: B005 | G30: Individual | H30: 45879
A31: C00030 | B31: 40 | C31: Female | D31: Lusaka | E31: Lusaka | F31: B001 | G31: SME | H31: 45830
A32: C00031 | B32: 43 | C32: Female | D32: Copperbelt | E32: Kitwe | F32: B005 | G32: Student | H32: 44998
A33: C00032 | B33: 38 | C33: Female | D33: Lusaka | E33: Lusaka | F33: B002 | G33: Individual | H33: 46140
A34: C00033 | B34: 39 | C34: Male | D34: Lusaka | E34: Lusaka | F34: B001 | G34: Individual | H34: 45033
A35: C00034 | B35: 24 | C35: Female | D35: Eastern | E35: Chipata | F35: B010 | G35: Student | H35: 46182
A36: C00035 | B36: 31 | C36: Female | D36: Eastern | E36: Chipata | F36: B010 | G36: Individual | H36: 45992
A37: C00036 | B37: 32 | C37: Female | D37: Central | E37: Kabwe | F37: B008 | G37: Individual | H37: 45809
A38: C00037 | B38: 24 | C38: Female | D38: Lusaka | E38: Lusaka | F38: B003 | G38: Individual | H38: 45065
... A1001: C01000 | B1001: 40 | C1001: Male | D1001: Lusaka | E1001: Lusaka | F1001: B004 | G1001: Individual | H1001: 45766

Sheet Accounts
A1: Account_ID | B1: Customer_ID | C1: Account_Type | D1: Account_Status | E1: Opening_Balance | F1: Account_Open_Date | H1: Customer_ID_Check | K1: Customer Segment
A2: A000001 | B2: C00001 | C2: Savings | D2: Inactive | E2: 3663.33 | F2: 45575 | H2: =IF(COUNTIF(Customers!$A$2:$A$1001,B2)>0,"Valid","Invalid") -> Valid | I2: =IF(OR(C2="Savings",C2="Current",C2="Business",C2="Student"),"Valid","Check") -> Valid | K2: =VLOOKUP(B2,Customers!A:G,7,FALSE) -> Individual
A3: A000002 | B3: C00002 | C3: Student | D3: Inactive | E3: 5947.62 | F3: 46114 | H3: =IF(COUNTIF(Customers!$A$2:$A$1001,B3)>0,"Valid","Invalid") -> Valid | I3: =IF(OR(C3="Savings",C3="Current",C3="Business",C3="Student"),"Valid","Check") -> Valid | K3: =VLOOKUP(B3,Customers!A:G,7,FALSE) -> Student
A4: A000003 | B4: C00003 | C4: Business | D4: Active | E4: 2931.66 | F4: 45402 | H4: =IF(COUNTIF(Customers!$A$2:$A$1001,B4)>0,"Valid","Invalid") -> Valid | I4: =IF(OR(C4="Savings",C4="Current",C4="Business",C4="Student"),"Valid","Check") -> Valid | K4: =VLOOKUP(B4,Customers!A:G,7,FALSE) -> SME
A5: A000004 | B5: C00004 | C5: Business | D5: Active | E5: 5224.92 | F5: 45096 | H5: =IF(COUNTIF(Customers!$A$2:$A$1001,B5)>0,"Valid","Invalid") -> Valid | I5: =IF(OR(C5="Savings",C5="Current",C5="Business",C5="Student"),"Valid","Check") -> Valid | K5: =VLOOKUP(B5,Customers!A:G,7,FALSE) -> Individual
A6: A000005 | B6: C00005 | C6: Student | D6: Active | E6: 1867.77 | F6: 45100 | H6: =IF(COUNTIF(Customers!$A$2:$A$1001,B6)>0,"Valid","Invalid") -> Valid | I6: =IF(OR(C6="Savings",C6="Current",C6="Business",C6="Student"),"Valid","Check") -> Valid | K6: =VLOOKUP(B6,Customers!A:G,7,FALSE) -> SME
A7: A000006 | B7: C00006 | C7: Savings | D7: Active | E7: 4046.44 | F7: 45396 | H7: =IF(COUNTIF(Customers!$A$2:$A$1001,B7)>0,"Valid","Invalid") -> Valid | I7: =IF(OR(C7="Savings",C7="Current",C7="Business",C7="Student"),"Valid","Check") -> Valid | K7: =VLOOKUP(B7,Customers!A:G,7,FALSE) -> SME
A8: A000007 | B8: C00007 | C8: Savings | D8: Inactive | E8: 1949.67 | F8: 45271 | H8: =IF(COUNTIF(Customers!$A$2:$A$1001,B8)>0,"Valid","Invalid") -> Valid | I8: =IF(OR(C8="Savings",C8="Current",C8="Business",C8="Student"),"Valid","Check") -> Valid | K8: =VLOOKUP(B8,Customers!A:G,7,FALSE) -> Individual
A9: A000008 | B9: C00008 | C9: Current | D9: Active | E9: 648.77 | F9: 45371 | H9: =IF(COUNTIF(Customers!$A$2:$A$1001,B9)>0,"Valid","Invalid") -> Valid | I9: =IF(OR(C9="Savings",C9="Current",C9="Business",C9="Student"),"Valid","Check") -> Valid | K9: =VLOOKUP(B9,Customers!A:G,7,FALSE) -> Individual
A10: A000009 | B10: C00009 | C10: Savings | D10: Active | E10: 2313.97 | F10: 45968 | H10: =IF(COUNTIF(Customers!$A$2:$A$1001,B10)>0,"Valid","Invalid") -> Valid | I10: =IF(OR(C10="Savings",C10="Current",C10="Business",C10="Student"),"Valid","Check") -> Valid | K10: =VLOOKUP(B10,Customers!A:G,7,FALSE) -> Individual
A11: A000010 | B11: C00010 | C11: Savings | D11: Active | E11: 668.28 | F11: 46020 | H11: =IF(COUNTIF(Customers!$A$2:$A$1001,B11)>0,"Valid","Invalid") -> Valid | I11: =IF(OR(C11="Savings",C11="Current",C11="Business",C11="Student"),"Valid","Check") -> Valid | K11: =VLOOKUP(B11,Customers!A:G,7,FALSE) -> SME
A12: A000011 | B12: C00011 | C12: Savings | D12: Active | E12: 18753.37 | F12: 45554 | H12: =IF(COUNTIF(Customers!$A$2:$A$1001,B12)>0,"Valid","Invalid") -> Valid | I12: =IF(OR(C12="Savings",C12="Current",C12="Business",C12="Student"),"Valid","Check") -> Valid | K12: =VLOOKUP(B12,Customers!A:G,7,FALSE) -> Individual
A13: A000012 | B13: C00012 | C13: Current | D13: Inactive | E13: 1294.54 | F13: 45518 | H13: =IF(COUNTIF(Customers!$A$2:$A$1001,B13)>0,"Valid","Invalid") -> Valid | I13: =IF(OR(C13="Savings",C13="Current",C13="Business",C13="Student"),"Valid","Check") -> Valid | K13: =VLOOKUP(B13,Customers!A:G,7,FALSE) -> Individual
... A1001: A001000 | B1001: C01000 | C1001: Business | D1001: Active | E1001: 2844.82 | F1001: 46038 | H1001: =IF(COUNTIF(Customers!$A$2:$A$1001,B1001)>0,"Valid","Invalid") -> Valid | I1001: =IF(OR(C1001="Savings",C1001="Current",C1001="Business",C1001="Student"),"Valid","Check") -> Valid | K1001: =VLOOKUP(B1001,Customers!A:G,7,FALSE) -> Individual

Sheet EDA_CUSTOMERS
A1: Customer Segment | B1: Number of Customers | C1: Customer % | P1: Metric | Q1: Value
A2: Student | B2: =COUNTIF(Customers!G:G,A2) -> 118 | C2: =B2/$B$6 -> 0.118 | P2: Average Age | Q2: =AVERAGE(Customers!B2:B1001) -> 41.465
A3: Individual | B3: =COUNTIF(Customers!G:G,A3) -> 582 | C3: =B3/$B$6 -> 0.582 | P3: Minimum Age | Q3: =MIN(Customers!B2:B1001) -> 18
A4: SME | B4: =COUNTIF(Customers!G:G,A4) -> 237 | C4: =B4/$B$6 -> 0.237 | P4: Maximum Age | Q4: =MAX(Customers!B2:B1001) -> 65
A5: Corporate | B5: =COUNTIF(Customers!G:G,A5) -> 63 | C5: =B5/$B$6 -> 0.063
A6: Total | B6: =SUM(B2:B5) -> 1000 | C6: =SUM(C2:C5) -> 1
A9: Province | B9: Number of Customers | C9: Customer %
A10: Lusaka | B10: =COUNTIF(Customers!D:D,A10) -> 503 | C10: =B10/$B$16 -> 0.503
A11: Copperbelt | B11: =COUNTIF(Customers!D:D,A11) -> 219 | C11: =B11/$B$16 -> 0.219
A12: Central | B12: =COUNTIF(Customers!D:D,A12) -> 63 | C12: =B12/$B$16 -> 0.063
A13: Southern | B13: =COUNTIF(Customers!D:D,A13) -> 62 | C13: =B13/$B$16 -> 0.062
A14: Western | B14: =COUNTIF(Customers!D:D,A14) -> 85 | C14: =B14/$B$16 -> 0.085
A15: Eastern | B15: =COUNTIF(Customers!D:D,A15) -> 68 | C15: =B15/$B$16 -> 0.068
A16: Total | B16: =SUM(B10:B15) -> 1000 | C16: =SUM(C10:C15) -> 1
A19: Gender | B19: Number of Customers | C19: Customer %
A20: Male | B20: =COUNTIF(Customers!C:C, Customers!C2) -> 473 | C20: =B20/$B$23 -> 0.473
A21: Female | B21: =COUNTIF(Customers!C:C, Customers!C5) -> 523 | C21: =B21/$B$23 -> 0.523
A22: Unknown | B22: =COUNTIF(Customers!C:C, Customers!C14) -> 4 | C22: =B22/$B$23 -> 0.004
A23: Total | B23: =SUM(B20:B22) -> 1000 | C23: =SUM(C20:C22) -> 1
A27: Metric | B27: Value
A28: Average Age | B28: =AVERAGE(Customers!B2:B1001) -> 41.465
A29: Minimum Age | B29: =MIN(Customers!B3:B1002) -> 18
A30: Maximum Age | B30: =MAX(Customers!B4:B1003) -> 65
A34: Age Group | B34: Number of Customers | C34: Customer %
A35: 18–24 | B35: =COUNTIFS(Customers!B:B,">=18",Customers!B:B,"<=24") -> 137 | C35: =B35/$B$40 -> 0.137
A36: 25–34 | B36: =COUNTIFS(Customers!B:B,">=25",Customers!B:B,"<=34") -> 225 | C36: =B36/$B$40 -> 0.225
A37: 35–44 | B37: =COUNTIFS(Customers!B:B,">=35",Customers!B:B,"<=44") -> 198 | C37: =B37/$B$40 -> 0.198
A38: 45–54 | B38: =COUNTIFS(Customers!B:B,">=45",Customers!B:B,"<=54") -> 218 | C38: =B38/$B$40 -> 0.218
A39: 55–65 | B39: =COUNTIFS(Customers!B:B,">=55",Customers!B:B,"<=65") -> 222 | C39: =B39/$B$40 -> 0.222
A40: Total | B40: =SUM(B35:B39) -> 1000 | C40: =SUM(C35:C39) -> 1
A44: Year | B44: Customers Joined
A45: 2023 | B45: =COUNTIFS(Customers!H:H,">="&DATE(2023,1,1),Customers!H:H,"<"&DATE(2024,1,1)) -> 271
A46: 2024 | B46: =COUNTIFS(Customers!H:H,">="&DATE(2024,1,1),Customers!H:H,"<"&DATE(2025,1,1)) -> 299
A47: 2025 | B47: =COUNTIFS(Customers!H:H,">="&DATE(2025,1,1),Customers!H:H,"<"&DATE(2026,1,1)) -> 276
A48: 2026 | B48: =COUNTIFS(Customers!H:H,">="&DATE(2026,1,1),Customers!H:H,"<"&DATE(2027,1,1)) -> 154
A49: Total | B49: =SUM(B45:B48) -> 1000
A52: Account Type Distribution
A53: Account Type | B53: Number of Accounts | C53: Percentage
A54: Savings | B54: =COUNTIF(Accounts!C:C, Accounts!C2) -> 542 | C54: =B54/$B$58 -> 0.542
A55: Current | B55: =COUNTIF(Accounts!C:C, Accounts!C9) -> 178 | C55: =B55/$B$58 -> 0.178
...

Sheet Transactions
A1: Transaction_ID | B1: Customer_ID | C1: Transaction_Date | D1: Transaction_Type | E1: Channel | F1: Branch_ID | G1: Amount | H1: Transaction_Status | I1: Customer_Segment | Q1: Customer_ID_Check | R1: Branch_ID_Check
A2: T0000001 | B2: C00747 | C2: 46145 | D2: Transfer | E2: ATM | F2: B009 | G2: 1292.87 | H2: Completed | I2: =VLOOKUP(B2,Customers!A:G,7,FALSE) -> Individual | J2: =IF(LEN(E2)<>LEN(TRIM(E2)),"CHECK","") | M2: Row Labels | N2: Count of Transaction_Type | Q2: =IF(COUNTIF(Customers!$A$2:$A$1001,B2)>0,"Valid","Invalid") -> Valid | R2: =IF(COUNTIF(Branches!$A$2:$A$11,F2)>0,"Valid","Invalid") -> Valid
A3: T0000002 | B3: C00232 | C3: 46184 | D3: Payment | E3: Mobile Banking | F3: B002 | G3: 229.42 | H3: Completed | I3: =VLOOKUP(B3,Customers!A:G,7,FALSE) -> Student | J3: =IF(LEN(E3)<>LEN(TRIM(E3)),"CHECK","") | M3: Deposit | N3: 1586 | Q3: =IF(COUNTIF(Customers!$A$2:$A$1001,B3)>0,"Valid","Invalid") -> Valid | R3: =IF(COUNTIF(Branches!$A$2:$A$11,F3)>0,"Valid","Invalid") -> Valid
A4: T0000003 | B4: C00007 | C4: 46049 | D4: Deposit | E4: ATM | F4: B005 | G4: 1064.01 | H4: Completed | I4: =VLOOKUP(B4,Customers!A:G,7,FALSE) -> Individual | J4: =IF(LEN(E4)<>LEN(TRIM(E4)),"CHECK","") | M4: Loan Repayment | N4: 493 | Q4: =IF(COUNTIF(Customers!$A$2:$A$1001,B4)>0,"Valid","Invalid") -> Valid | R4: =IF(COUNTIF(Branches!$A$2:$A$11,F4)>0,"Valid","Invalid") -> Valid
A5: T0000004 | B5: C00804 | C5: 46035 | D5: Withdrawal | E5: Internet Banking | F5: B004 | G5: 462.26 | H5: Completed | I5: =VLOOKUP(B5,Customers!A:G,7,FALSE) -> Individual | J5: =IF(LEN(E5)<>LEN(TRIM(E5)),"CHECK","") | M5: Payment | N5: 1353 | Q5: =IF(COUNTIF(Customers!$A$2:$A$1001,B5)>0,"Valid","Invalid") -> Valid | R5: =IF(COUNTIF(Branches!$A$2:$A$11,F5)>0,"Valid","Invalid") -> Valid
A6: T0000005 | B6: C00550 | C6: 46250 | D6: Loan Repayment | E6: ATM | F6: B007 | G6: 267.93 | H6: Completed | I6: =VLOOKUP(B6,Customers!A:G,7,FALSE) -> Individual | J6: =IF(LEN(E6)<>LEN(TRIM(E6)),"CHECK","") | M6: Transfer | N6: 1355 | Q6: =IF(COUNTIF(Customers!$A$2:$A$1001,B6)>0,"Valid","Invalid") -> Valid | R6: =IF(COUNTIF(Branches!$A$2:$A$11,F6)>0,"Valid","Invalid") -> Valid
A7: T0000006 | B7: C00976 | C7: 46177 | D7: Withdrawal | E7: Mobile Banking | F7: B003 | G7: 607.99 | H7: Completed | I7: =VLOOKUP(B7,Customers!A:G,7,FALSE) -> SME | J7: =IF(LEN(E7)<>LEN(TRIM(E7)),"CHECK","") | M7: Withdrawal | N7: 1216 | Q7: =IF(COUNTIF(Customers!$A$2:$A$1001,B7)>0,"Valid","Invalid") -> Valid | R7: =IF(COUNTIF(Branches!$A$2:$A$11,F7)>0,"Valid","Invalid") -> Valid
A8: T0000007 | B8: C00052 | C8: 46095 | D8: Withdrawal | E8: POS | F8: B006 | G8: 975.78 | H8: Completed | I8: =VLOOKUP(B8,Customers!A:G,7,FALSE) -> Student | J8: =IF(LEN(E8)<>LEN(TRIM(E8)),"CHECK","") | M8: Grand Total | N8: 6003 | Q8: =IF(COUNTIF(Customers!$A$2:$A$1001,B8)>0,"Valid","Invalid") -> Valid | R8: =IF(COUNTIF(Branches!$A$2:$A$11,F8)>0,"Valid","Invalid") -> Valid
A9: T0000008 | B9: C00655 | C9: 46219 | D9: Loan Repayment | E9: Internet Banking | F9: B003 | G9: 1042.81 | H9: Completed | I9: =VLOOKUP(B9,Customers!A:G,7,FALSE) -> Individual | J9: =IF(LEN(E9)<>LEN(TRIM(E9)),"CHECK","") | Q9: =IF(COUNTIF(Customers!$A$2:$A$1001,B9)>0,"Valid","Invalid") -> Valid | R9: =IF(COUNTIF(Branches!$A$2:$A$11,F9)>0,"Valid","Invalid") -> Valid
A10: T0000009 | B10: C00942 | C10: 46265 | D10: Deposit | E10: Branch | F10: B001 | G10: 2335.6 | H10: Completed | I10: =VLOOKUP(B10,Customers!A:G,7,FALSE) -> Individual | J10: =IF(LEN(E10)<>LEN(TRIM(E10)),"CHECK","") | Q10: =IF(COUNTIF(Customers!$A$2:$A$1001,B10)>0,"Valid","Invalid") -> Valid | R10: =IF(COUNTIF(Branches!$A$2:$A$11,F10)>0,"Valid","Invalid") -> Valid
A11: T0000010 | B11: C00919 | C11: 46108 | D11: Deposit | E11: Mobile Banking | F11: B001 | G11: 3002.83 | H11: Completed | I11: =VLOOKUP(B11,Customers!A:G,7,FALSE) -> Individual | J11: =IF(LEN(E11)<>LEN(TRIM(E11)),"CHECK","") | Q11: =IF(COUNTIF(Customers!$A$2:$A$1001,B11)>0,"Valid","Invalid") -> Valid | R11: =IF(COUNTIF(Branches!$A$2:$A$11,F11)>0,"Valid","Invalid") -> Valid
A12: T0000011 | B12: C00396 | C12: 46053 | D12: Payment | E12: Mobile Banking | F12: B001 | G12: 1137.15 | H12: Completed | I12: =VLOOKUP(B12,Customers!A:G,7,FALSE) -> Individual | J12: =IF(LEN(E12)<>LEN(TRIM(E12)),"CHECK","") | K12: Date max | L12: =MAX(C:C) -> 46265 | Q12: =IF(COUNTIF(Customers!$A$2:$A$1001,B12)>0,"Valid","Invalid") -> Valid | R12: =IF(COUNTIF(Branches!$A$2:$A$11,F12)>0,"Valid","Invalid") -> Valid
A13: T0000012 | B13: C00221 | C13: 46025 | D13: Payment | E13: Mobile Banking | F13: B001 | G13: 1362.54 | H13: Completed | I13: =VLOOKUP(B13,Customers!A:G,7,FALSE) -> SME | J13: =IF(LEN(E13)<>LEN(TRIM(E13)),"CHECK","") | K13: Date Min | L13: =MIN(C:C) -> 46023 | Q13: =IF(COUNTIF(Customers!$A$2:$A$1001,B13)>0,"Valid","Invalid") -> Valid | R13: =IF(COUNTIF(Branches!$A$2:$A$11,F13)>0,"Valid","Invalid") -> Valid
A14: T0000013 | B14: C00428 | C14: 46052 | D14: Withdrawal | E14: Branch | F14: B005 | G14: 893.65 | H14: Completed | I14: =VLOOKUP(B14,Customers!A:G,7,FALSE) -> Corporate | J14: =IF(LEN(E14)<>LEN(TRIM(E14)),"CHECK","") | Q14: =IF(COUNTIF(Customers!$A$2:$A$1001,B14)>0,"Valid","Invalid") -> Valid | R14: =IF(COUNTIF(Branches!$A$2:$A$11,F14)>0,"Valid","Invalid") -> Valid
A15: T0000014 | B15: C00752 | C15: 46171 | D15: Transfer | E15: Mobile Banking | F15: B006 | G15: 1749.75 | H15: Completed | I15: =VLOOKUP(B15,Customers!A:G,7,FALSE) -> Individual | J15: =IF(LEN(E15)<>LEN(TRIM(E15)),"CHECK","") | Q15: =IF(COUNTIF(Customers!$A$2:$A$1001,B15)>0,"Valid","Invalid") -> Valid | R15: =IF(COUNTIF(Branches!$A$2:$A$11,F15)>0,"Valid","Invalid") -> Valid
A16: T0000015 | B16: C00143 | C16: 46121 | D16: Payment | E16: Internet Banking | F16: B001 | G16: 1322.12 | H16: Completed | I16: =VLOOKUP(B16,Customers!A:G,7,FALSE) -> Individual | J16: =IF(LEN(E16)<>LEN(TRIM(E16)),"CHECK","") | Q16: =IF(COUNTIF(Customers!$A$2:$A$1001,B16)>0,"Valid","Invalid") -> Valid | R16: =IF(COUNTIF(Branches!$A$2:$A$11,F16)>0,"Valid","Invalid") -> Valid
A17: T0000016 | B17: C00861 | C17: 46156 | D17: Payment | E17: POS | F17: B006 | G17: 769.32 | H17: Completed | I17: =VLOOKUP(B17,Customers!A:G,7,FALSE) -> Corporate | J17: =IF(LEN(E17)<>LEN(TRIM(E17)),"CHECK","") | Q17: =IF(COUNTIF(Customers!$A$2:$A$1001,B17)>0,"Valid","Invalid") -> Valid | R17: =IF(COUNTIF(Branches!$A$2:$A$11,F17)>0,"Valid","Invalid") -> Valid
A18: T0000017 | B18: C00363 | C18: 46242 | D18: Deposit | E18: ATM | F18: B005 | G18: 6988.23 | H18: Completed | I18: =VLOOKUP(B18,Customers!A:G,7,FALSE) -> Individual | J18: =IF(LEN(E18)<>LEN(TRIM(E18)),"CHECK","") | Q18: =IF(COUNTIF(Customers!$A$2:$A$1001,B18)>0,"Valid","Invalid") -> Valid | R18: =IF(COUNTIF(Branches!$A$2:$A$11,F18)>0,"Valid","Invalid") -> Valid
A19: T0000018 | B19: C00382 | C19: 46182 | D19: Deposit | E19: ATM | F19: B001 | G19: 470.51 | H19: Completed | I19: =VLOOKUP(B19,Customers!A:G,7,FALSE) -> Student | J19: =IF(LEN(E19)<>LEN(TRIM(E19)),"CHECK","") | Q19: =IF(COUNTIF(Customers!$A$2:$A$1001,B19)>0,"Valid","Invalid") -> Valid | R19: =IF(COUNTIF(Branches!$A$2:$A$11,F19)>0,"Valid","Invalid") -> Valid
A20: T0000019 | B20: C00561 | C20: 46192 | D20: Withdrawal | E20: Branch | F20: B003 | G20: 3478.85 | H20: Completed | I20: =VLOOKUP(B20,Customers!A:G,7,FALSE) -> Individual | J20: =IF(LEN(E20)<>LEN(TRIM(E20)),"CHECK","") | Q20: =IF(COUNTIF(Customers!$A$2:$A$1001,B20)>0,"Valid","Invalid") -> Valid | R20: =IF(COUNTIF(Branches!$A$2:$A$11,F20)>0,"Valid","Invalid") -> Valid
A21: T0000020 | B21: C00277 | C21: 46251 | D21: Payment | E21: POS | F21: B007 | G21: 209.71 | H21: Completed | I21: =VLOOKUP(B21,Customers!A:G,7,FALSE) -> SME | Q21: =IF(COUNTIF(Customers!$A$2:$A$1001,B21)>0,"Valid","Invalid") -> Valid | R21: =IF(COUNTIF(Branches!$A$2:$A$11,F21)>0,"Valid","Invalid") -> Valid
A22: T0000021 | B22: C00271 | C22: 46212 | D22: Payment | E22: Internet Banking | F22: B001 | G22: 1832.83 | H22: Completed | I22: =VLOOKUP(B22,Customers!A:G,7,FALSE) -> SME | M22: Row Labels | N22: Count of Channel | Q22: =IF(COUNTIF(Customers!$A$2:$A$1001,B22)>0,"Valid","Invalid") -> Valid | R22: =IF(COUNTIF(Branches!$A$2:$A$11,F22)>0,"Valid","Invalid") -> Valid
A23: T0000022 | B23: C00014 | C23: 46239 | D23: Loan Repayment | E23: Mobile Banking | F23: B001 | G23: 3417.17 | H23: Completed | I23: =VLOOKUP(B23,Customers!A:G,7,FALSE) -> Individual | M23: MOBILE BANKING | N23: 1 | Q23: =IF(COUNTIF(Customers!$A$2:$A$1001,B23)>0,"Valid","Invalid") -> Valid | R23: =IF(COUNTIF(Branches!$A$2:$A$11,F23)>0,"Valid","Invalid") -> Valid
A24: T0000023 | B24: C00298 | C24: 46182 | D24: Payment | E24: Mobile Banking | F24: B010 | G24: 120.64 | H24: Completed | I24: =VLOOKUP(B24,Customers!A:G,7,FALSE) -> SME | M24: ATM | N24: 1486 | Q24: =IF(COUNTIF(Customers!$A$2:$A$1001,B24)>0,"Valid","Invalid") -> Valid | R24: =IF(COUNTIF(Branches!$A$2:$A$11,F24)>0,"Valid","Invalid") -> Valid
A25: T0000024 | B25: C00464 | C25: 46121 | D25: Transfer | E25: Internet Banking | F25: B007 | G25: 933.51 | H25: Completed | I25: =VLOOKUP(B25,Customers!A:G,7,FALSE) -> SME | M25: ATM | N25: 1 | Q25: =IF(COUNTIF(Customers!$A$2:$A$1001,B25)>0,"Valid","Invalid") -> Valid | R25: =IF(COUNTIF(Branches!$A$2:$A$11,F25)>0,"Valid","Invalid") -> Valid
A26: T0000025 | B26: C00527 | C26: 46108 | D26: Withdrawal | E26: Branch | F26: B004 | G26: 1661.4 | H26: Completed | I26: =VLOOKUP(B26,Customers!A:G,7,FALSE) -> SME | M26: Branch | N26: 1020 | Q26: =IF(COUNTIF(Customers!$A$2:$A$1001,B26)>0,"Valid","Invalid") -> Valid | R26: =IF(COUNTIF(Branches!$A$2:$A$11,F26)>0,"Valid","Invalid") -> Valid
A27: T0000026 | B27: C00234 | C27: 46238 | D27: Payment | E27: Mobile Banking | F27: B006 | G27: 1045.2 | H27: Completed | I27: =VLOOKUP(B27,Customers!A:G,7,FALSE) -> Corporate | M27: Internet Banking | N27: 882 | Q27: =IF(COUNTIF(Customers!$A$2:$A$1001,B27)>0,"Valid","Invalid") -> Valid | R27: =IF(COUNTIF(Branches!$A$2:$A$11,F27)>0,"Valid","Invalid") -> Valid
A28: T0000027 | B28: C00575 | C28: 46189 | D28: Payment | E28: ATM | F28: B008 | G28: 1185.78 | H28: Completed | I28: =VLOOKUP(B28,Customers!A:G,7,FALSE) -> Individual | M28: Mobile Banking | N28: 1987 | Q28: =IF(COUNTIF(Customers!$A$2:$A$1001,B28)>0,"Valid","Invalid") -> Valid | R28: =IF(COUNTIF(Branches!$A$2:$A$11,F28)>0,"Valid","Invalid") -> Valid
A29: T0000028 | B29: C00708 | C29: 46086 | D29: Transfer | E29: Internet Banking | F29: B008 | G29: 930.97 | H29: Completed | I29: =VLOOKUP(B29,Customers!A:G,7,FALSE) -> Individual | M29: POS | N29: 626 | Q29: =IF(COUNTIF(Customers!$A$2:$A$1001,B29)>0,"Valid","Invalid") -> Valid | R29: =IF(COUNTIF(Branches!$A$2:$A$11,F29)>0,"Valid","Invalid") -> Valid
A30: T0000029 | B30: C00027 | C30: 46140 | D30: Deposit | E30: Mobile Banking | F30: B003 | G30: 271.99 | H30: Completed | I30: =VLOOKUP(B30,Customers!A:G,7,FALSE) -> Student | M30: Grand Total | N30: 6003 | Q30: =IF(COUNTIF(Customers!$A$2:$A$1001,B30)>0,"Valid","Invalid") -> Valid | R30: =IF(COUNTIF(Branches!$A$2:$A$11,F30)>0,"Valid","Invalid") -> Valid
A31: T0000030 | B31: C00471 | C31: 46180 | D31: Loan Repayment | E31: Internet Banking | F31: B004 | G31: 8673.66 | H31: Completed | I31: =VLOOKUP(B31,Customers!A:G,7,FALSE) -> Student | Q31: =IF(COUNTIF(Customers!$A$2:$A$1001,B31)>0,"Valid","Invalid") -> Valid | R31: =IF(COUNTIF(Branches!$A$2:$A$11,F31)>0,"Valid","Invalid") -> Valid
A32: T0000031 | B32: C00093 | C32: 46213 | D32: Withdrawal | E32: Mobile Banking | F32: B006 | G32: 491.01 | H32: Completed | I32: =VLOOKUP(B32,Customers!A:G,7,FALSE) -> Individual | Q32: =IF(COUNTIF(Customers!$A$2:$A$1001,B32)>0,"Valid","Invalid") -> Valid | R32: =IF(COUNTIF(Branches!$A$2:$A$11,F32)>0,"Valid","Invalid") -> Valid
A33: T0000032 | B33: C00617 | C33: 46136 | D33: Withdrawal | E33: Internet Banking | F33: B001 | G33: 1254.08 | H33: Completed | I33: =VLOOKUP(B33,Customers!A:G,7,FALSE) -> Individual | Q33: =IF(COUNTIF(Customers!$A$2:$A$1001,B33)>0,"Valid","Invalid") -> Valid | R33: =IF(COUNTIF(Branches!$A$2:$A$11,F33)>0,"Valid","Invalid") -> Valid
A34: T0000033 | B34: C00309 | C34: 46246 | D34: Transfer | E34: Branch | F34: B010 | G34: 425.46 | H34: Completed | I34: =VLOOKUP(B34,Customers!A:G,7,FALSE) -> Individual | Q34: =IF(COUNTIF(Customers!$A$2:$A$1001,B34)>0,"Valid","Invalid") -> Valid | R34: =IF(COUNTIF(Branches!$A$2:$A$11,F34)>0,"Valid","Invalid") -> Valid
A35: T0000034 | B35: C00052 | C35: 46181 | D35: Transfer | E35: Mobile Banking | F35: B004 | G35: 83.44 | H35: Completed | I35: =VLOOKUP(B35,Customers!A:G,7,FALSE) -> Student | Q35: =IF(COUNTIF(Customers!$A$2:$A$1001,B35)>0,"Valid","Invalid") -> Valid | R35: =IF(COUNTIF(Branches!$A$2:$A$11,F35)>0,"Valid","Invalid") -> Valid
A36: T0000035 | B36: C00319 | C36: 46109 | D36: Deposit | E36: Branch | F36: B003 | G36: 322.3 | H36: Completed | I36: =VLOOKUP(B36,Customers!A:G,7,FALSE) -> Individual | Q36: =IF(COUNTIF(Customers!$A$2:$A$1001,B36)>0,"Valid","Invalid") -> Valid | R36: =IF(COUNTIF(Branches!$A$2:$A$11,F36)>0,"Valid","Invalid") -> Valid
A37: T0000036 | B37: C00969 | C37: 46062 | D37: Payment | E37: Internet Banking | F37: B009 | G37: 191.02 | H37: Completed | I37: =VLOOKUP(B37,Customers!A:G,7,FALSE) -> Individual | Q37: =IF(COUNTIF(Customers!$A$2:$A$1001,B37)>0,"Valid","Invalid") -> Valid | R37: =IF(COUNTIF(Branches!$A$2:$A$11,F37)>0,"Valid","Invalid") -> Valid
A38: T0000037 | B38: C00181 | C38: 46183 | D38: Withdrawal | E38: POS | F38: B001 | G38: 2420.11 | H38: Completed | I38: =VLOOKUP(B38,Customers!A:G,7,FALSE) -> Student | Q38: =IF(COUNTIF(Customers!$A$2:$A$1001,B38)>0,"Valid","Invalid") -> Valid | R38: =IF(COUNTIF(Branches!$A$2:$A$11,F38)>0,"Valid","Invalid") -> Valid
A39: T0000038 | B39: C00569 | C39: 46213 | D39: Deposit | E39: ATM | F39: B001 | G39: 442.81 | H39: Completed | I39: =VLOOKUP(B39,Customers!A:G,7,FALSE) -> Individual | Q39: =IF(COUNTIF(Customers!$A$2:$A$1001,B39)>0,"Valid","Invalid") -> Valid | R39: =IF(COUNTIF(Branches!$A$2:$A$11,F39)>0,"Valid","Invalid") -> Valid
A40: T0000039 | B40: C00120 | C40: 46047 | D40: Withdrawal | E40: Branch | F40: B006 | G40: 485.85 | H40: Reversed | I40: =VLOOKUP(B40,Customers!A:G,7,FALSE) -> Individual | Q40: =IF(COUNTIF(Customers!$A$2:$A$1001,B40)>0,"Valid","Invalid") -> Valid | R40: =IF(COUNTIF(Branches!$A$2:$A$11,F40)>0,"Valid","Invalid") -> Valid
...

Sheet VALIDATION_RESULTS
A1: Validation | B1: Expected Result | C1: Actual Result | D1: Status | H1: Validation | I1: Expected Result | J1: Actual Result | K1: Status
A2: Customer_ID uniqueness | B2: No duplicates | C2: 0 duplicates | D2: PASS | H2: Loan Amount validity | I2: No values ≤ 0 | J2: 0 | K2: PASS
A3: Account → Customer | B3: 0 invalid | C3: 0 invalid | D3: PASS | H3: Loan Amount completeness | I3: 0 missing | J3: 0 | K3: PASS
A4: Transaction_ID completeness | B4: 0 missing | C4: 3 missing | D4: FAIL | H4: Loan Interest Rate | I4: 10%–35%
A5: Transaction → Customer | B5: 0 invalid | C5: 0 invalid | D5: PASS | H5: Loan Term | I5: 3,6,12,24 | J5: Valid terms only | K5: PASS
A6: Transaction → Branch | B6: 0 invalid | C6: 0 invalid | D6: PASS | H6: Account Type | I6: Savings, Current, Business, Student only | J6: All valid, no blanks | K6: PASS
A7: Loan → Customer | B7: 0 invalid | C7: 0 invalid | D7: PASS | H7: Account Status | I7: Active, Inactive, Dormant, Closed only | J7: All valid, no blanks | K7: PASS
H8: Transaction Type | I8: Deposit, Withdrawal, Transfer, Payment, Loan Repayment only | J8: All valid | K8: PASS
H9: Transaction Type | I9: 5 valid categories | J9: All valid | K9: PASS
H10: Transaction Channel | I10: 5 valid categories | J10: All valid | K10: PASS
H11: Transaction Status | I11: 3 valid categories | J11: All valid | K11: PASS

Sheet Loans
A1: Loan_ID | B1: Customer_ID | C1: Loan_Type | D1: Loan_Amount | E1: Loan_Status | F1: Application_Date | G1: Interest_Rate | H1: Loan_Term_Months
A2: L00001 | B2: C00974 | C2: Salary Advance | D2: 3502.93 | E2: Active | F2: 45905 | G2: 31.22 | H2: 24 | L2: Row Labels | M2: Count of Loan_Type
A3: L00002 | B3: C00514 | C3: Salary Advance | D3: 17350.65 | E3: Active | F3: 46162 | G3: 17.43 | H3: 12 | L3: Agricultural | M3: 48
A4: L00003 | B4: C00453 | C4: Personal | D4: 9657.24 | E4: Active | F4: 46010 | G4: 21.29 | H4: 24 | L4: Personal | M4: 207
A5: L00004 | B5: C00132 | C5: Salary Advance | D5: 8862.28 | E5: Active | F5: 45801 | G5: 25.84 | H5: 12 | L5: Salary Advance | M5: 97
A6: L00005 | B6: C00716 | C6: Personal | D6: 26228.41 | E6: Paid | F6: 46007 | G6: 16.47 | H6: 6 | L6: SME | M6: 98
A7: L00006 | B7: C00691 | C7: Personal | D7: 22925.68 | E7: Active | F7: 46172 | G7: 26.43 | H7: 36 | L7: Grand Total | M7: 450
A8: L00007 | B8: C00040 | C8: Salary Advance | D8: 35970.61 | E8: Paid | F8: 45974 | G8: 17.22 | H8: 12
A9: L00008 | B9: C00589 | C9: Personal | D9: 24585.37 | E9: Active | F9: 45683 | G9: 22.11 | H9: 6
A10: L00009 | B10: C00707 | C10: Salary Advance | D10: 20822.63 | E10: Active | F10: 46187 | G10: 10.58 | H10: 36 | L10: Row Labels | M10: Count of Loan_Status
A11: L00010 | B11: C00158 | C11: Personal | D11: 11534.99 | E11: Paid | F11: 45979 | G11: 11.95 | H11: 36 | L11: Active | M11: 256
A12: L00011 | B12: C00173 | C12: Personal | D12: 8591.22 | E12: Active | F12: 45953 | G12: 15.68 | H12: 24 | L12: Defaulted | M12: 24
A13: L00012 | B13: C00587 | C13: SME | D13: 29123.23 | E13: Active | F13: 45788 | G13: 30.16 | H13: 48 | L13: Paid | M13: 135
A14: L00013 | B14: C00689 | C14: Personal | D14: 14696.04 | E14: Active | F14: 45674 | G14: 26.51 | H14: 36 | L14: Rejected | M14: 35
A15: L00014 | B15: C00632 | C15: Personal | D15: 24819.21 | E15: Active | F15: 46239 | G15: 32.34 | H15: 36 | L15: Grand Total | M15: 450
A16: L00015 | B16: C00617 | C16: SME | D16: 17968.76 | E16: Active | F16: 45842 | G16: 32.62 | H16: 6
A17: L00016 | B17: C00857 | C17: Personal | D17: 3516.14 | E17: Paid | F17: 45706 | G17: 19.37 | H17: 12
A18: L00017 | B18: C00976 | C18: Salary Advance | D18: 26550.41 | E18: Active | F18: 45733 | G18: 19.19 | H18: 12 | L18: Lowest intrest rate | M18: =MIN(G2:G451) -> 10.01
A19: L00018 | B19: C00357 | C19: Salary Advance | D19: 10930.36 | E19: Rejected | F19: 46185 | G19: 30.89 | H19: 36 | L19: Highest intrest rate | M19: =MAX(G3:G452) -> 34.97
A20: L00019 | B20: C00086 | C20: SME | D20: 36003.04 | E20: Active | F20: 45663 | G20: 20.66 | H20: 36
A21: L00020 | B21: C00931 | C21: Personal | D21: 4076.13 | E21: Active | F21: 45691 | G21: 31.43 | H21: 24
A22: L00021 | B22: C00549 | C22: SME | D22: 82392.41 | E22: Defaulted | F22: 45716 | G22: 22.65 | H22: 12
A23: L00022 | B23: C00767 | C23: Salary Advance | D23: 11194.83 | E23: Active | F23: 45724 | G23: 20.62 | H23: 6
A24: L00023 | B24: C00370 | C24: Personal | D24: 26290.3 | E24: Rejected | F24: 45912 | G24: 16.98 | H24: 3
A25: L00024 | B25: C00823 | C25: Personal | D25: 10197.91 | E25: Active | F25: 46060 | G25: 13.16 | H25: 24
A26: L00025 | B26: C00363 | C26: Salary Advance | D26: 11369.29 | E26: Active | F26: 45814 | G26: 23.15 | H26: 48
A27: L00026 | B27: C00253 | C27: Personal | D27: 31202.01 | E27: Active | F27: 45689 | G27: 18.13 | H27: 12
A28: L00027 | B28: C00102 | C28: SME | D28: 15342.55 | E28: Active | F28: 45667 | G28: 16.24 | H28: 24
A29: L00028 | B29: C00564 | C29: Personal | D29: 16219.08 | E29: Paid | F29: 46032 | G29: 14.24 | H29: 36
A30: L00029 | B30: C00203 | C30: Salary Advance | D30: 35581.1 | E30: Active | F30: 46006 | G30: 19.72 | H30: 6
A31: L00030 | B31: C00093 | C31: Personal | D31: 20976.25 | E31: Active | F31: 46246 | G31: 23.9 | H31: 36
... A451: L00450 | B451: C00077 | C451: Personal | D451: 7226.86 | E451: Active | F451: 45913 | G451: 19.39 | H451: 48

Sheet Branches
A1: Branch_ID | B1: Branch_Name | C1: Province | D1: City
A2: B001 | B2: Lusaka Main | C2: Lusaka | D2: Lusaka
A3: B002 | B3: Manda Hill | C3: Lusaka | D3: Lusaka
A4: B003 | B4: Cairo Road | C4: Lusaka | D4: Lusaka
A5: B004 | B5: Woodlands | C5: Lusaka | D5: Lusaka
A6: B005 | B6: Kitwe | C6: Copperbelt | D6: Kitwe
A7: B006 | B7: Ndola | C7: Copperbelt | D7: Ndola
A8: B007 | B8: Livingstone | C8: Southern | D8: Livingstone
A9: B008 | B9: Kabwe | C9: Central | D9: Kabwe
A10: B009 | B10: Mongu | C10: Western | D10: Mongu
A11: B010 | B11: Chipata | C11: Eastern | D11: Chipata

Sheet DATA_PROFILE
A1: Table | B1: Column | C1: Check | D1: Finding | E1: Severity
A2: Customers | B2: Customer_ID | C2: Duplicates | D2: 0 duplicates | E2: None
A3: Customers | B3: Gender | C3: Missing values | D3: 4 missing values | E3: Low
A4: Customers | B4: Province | C4: Consistency | D4: Lusaka and Lusaka Province used for the same province | E4: Low
A5: Customers | B5: Age | C5: Range | D5: 18–65 | E5: None
A6: Customers | B6: City | C6: Consistency | D6: No issue identified | E6: None
A7: Customers | B7: Branch_ID | C7: Completeness | D7: No missing values identified | E7: None
A8: Customers | B8: Customer_Segment | C8: Consistency | D8: No issue identified | E8: None
A9: Customers | B9: Join_Date | C9: Date validity | D9: No issue identified | E9: None
A10: Accounts | B10: Account_ID | C10: Duplicates | D10: 0 duplicates | E10: None
A11: Accounts | B11: Customer_ID | C11: Referential integrity | D11: No issue identified | E11: None
A12: Accounts | B12: Account_Type | C12: Consistency | D12: No issue identified | E12: None
... A36: Branches | B36: City | C36: Consistency | D36: No issue identified | E36: None
A37: Zero transaction amount | B37: Transactions | C37: 1 transaction has Amount = 0 | D37: Medium
A38: Negative transaction amount | B38: Transactions | C38: 1 transaction has Amount = -500 | D38: Medium

Sheet DATA_QUALITY_NOTES
A1: Issue_Type | B1: Affected_Table | C1: Description
A2: Missing Values | B2: Customers | C2: Some customer gender values are missing.
A3: Missing Values | B3: Transactions | C3: Some transaction amounts are missing.
A4: Inconsistent Text | B4: Transactions | C4: Some channel values use inconsistent capitalisation.
A5: Inconsistent Text | B5: Customers | C5: Some geographical values are inconsistent.
A6: Duplicate Records | B6: Transactions | C6: A small number of transaction records have been duplicated.
A7: Invalid/Unusual Values | B7: Transactions | C7: Some transaction amounts require investigation.
A8: Whitespace | B8: Customers/Accounts | C8: Some text values contain leading or trailing spaces.
A9: Inconsistent Geography | B9: Customers | C9: A small number of province values use inconsistent naming.

Sheet CLEANING LOG 
A1: Issue | B1: Table | C1: Action | D1: Result
A2: Zero transaction amount | B2: Transactions | C2: Flagged completed deposit with Amount = 0 as invalid | D2: Flagged
A3: Negative transaction amount | B3: Transactions | C3: Flagged completed deposit with Amount = -500 as invalid | D3: Flagged
A4: Province and City inconsistency | B4: Customers | C4: Changed Province from Lusaka Province to Central based on City and Branch_ID | D4: Completed
A5: Missing Transaction_ID | B5: Transactions | C5: Flagged records with missing primary identifiers | D5: Pending
